Workbook

Sheet Aggregate
B2: PyTRIM versus Legacy TRIM Comparison (Tier 1 Layout, Averaged Over 6 Chemicals)
B4: Compartment Type | C4: Average Ratio of pyTRIM to Legacy TRIM | D4: Max Ratio of pyTRIM to Legacy TRIM | E4: Min Ratio of pyTRIM to Legacy TRIM
B5: Surface water | C5: =AVERAGE(methylmercury!F2,divalent_mercury!F3,benzo_a_pyrene!F2,'2_3_7_8_tcdd'!F2,'cadmium'!F2,arsenic!F2) -> 1.0083333 | D5: =MAX(methylmercury!F2,divalent_mercury!F3,benzo_a_pyrene!F2,'2_3_7_8_tcdd'!F2,'cadmium'!F2,arsenic!F2) -> 1.05 | E5: =MIN(methylmercury!F2,divalent_mercury!F3,benzo_a_pyrene!F2,'2_3_7_8_tcdd'!F2,'cadmium'!F2,arsenic!F2) -> 0.98
B6: Sediment | C6: =AVERAGE(methylmercury!F3,divalent_mercury!F4,benzo_a_pyrene!F3,'2_3_7_8_tcdd'!F3,'cadmium'!F3,arsenic!F3) -> 1.0066667 | D6: =MAX(methylmercury!F3,divalent_mercury!F4,benzo_a_pyrene!F3,'2_3_7_8_tcdd'!F3,'cadmium'!F3,arsenic!F3) -> 1.05 | E6: =MIN(methylmercury!F3,divalent_mercury!F4,benzo_a_pyrene!F3,'2_3_7_8_tcdd'!F3,'cadmium'!F3,arsenic!F3) -> 0.98
B7: Macrophyte | C7: =AVERAGE(methylmercury!F4,divalent_mercury!F5,benzo_a_pyrene!F4,'2_3_7_8_tcdd'!F4,'cadmium'!F4,arsenic!F4) -> 1.0083333 | D7: =MAX(methylmercury!F4,divalent_mercury!F5,benzo_a_pyrene!F4,'2_3_7_8_tcdd'!F4,'cadmium'!F4,arsenic!F4) -> 1.05 | E7: =MIN(methylmercury!F4,divalent_mercury!F5,benzo_a_pyrene!F4,'2_3_7_8_tcdd'!F4,'cadmium'!F4,arsenic!F4) -> 0.98
B8: Zooplankton | C8: =AVERAGE(methylmercury!F5,divalent_mercury!F6,benzo_a_pyrene!F5,'2_3_7_8_tcdd'!F5,'cadmium'!F5,arsenic!F5) -> 1.0083333 | D8: =MAX(methylmercury!F5,divalent_mercury!F6,benzo_a_pyrene!F5,'2_3_7_8_tcdd'!F5,'cadmium'!F5,arsenic!F5) -> 1.05 | E8: =MIN(methylmercury!F5,divalent_mercury!F6,benzo_a_pyrene!F5,'2_3_7_8_tcdd'!F5,'cadmium'!F5,arsenic!F5) -> 0.98
B9: Water column herbivore | C9: =AVERAGE(methylmercury!F6,divalent_mercury!F7,benzo_a_pyrene!F6,'2_3_7_8_tcdd'!F6,'cadmium'!F6,arsenic!F6) -> 1.0083333 | D9: =MAX(methylmercury!F6,divalent_mercury!F7,benzo_a_pyrene!F6,'2_3_7_8_tcdd'!F6,'cadmium'!F6,arsenic!F6) -> 1.05 | E9: =MIN(methylmercury!F6,divalent_mercury!F7,benzo_a_pyrene!F6,'2_3_7_8_tcdd'!F6,'cadmium'!F6,arsenic!F6) -> 0.98
B10: Water column omnivore | C10: =AVERAGE(methylmercury!F7,divalent_mercury!F8,benzo_a_pyrene!F7,'2_3_7_8_tcdd'!F7,'cadmium'!F7,arsenic!F7) -> 1.0083333 | D10: =MAX(methylmercury!F7,divalent_mercury!F8,benzo_a_pyrene!F7,'2_3_7_8_tcdd'!F7,'cadmium'!F7,arsenic!F7) -> 1.05 | E10: =MIN(methylmercury!F7,divalent_mercury!F8,benzo_a_pyrene!F7,'2_3_7_8_tcdd'!F7,'cadmium'!F7,arsenic!F7) -> 0.98
B11: Water column carnivore | C11: =AVERAGE(methylmercury!F8,divalent_mercury!F9,benzo_a_pyrene!F8,'2_3_7_8_tcdd'!F8,'cadmium'!F8,arsenic!F8) -> 1.0083333 | D11: =MAX(methylmercury!F8,divalent_mercury!F9,benzo_a_pyrene!F8,'2_3_7_8_tcdd'!F8,'cadmium'!F8,arsenic!F8) -> 1.05 | E11: =MIN(methylmercury!F8,divalent_mercury!F9,benzo_a_pyrene!F8,'2_3_7_8_tcdd'!F8,'cadmium'!F8,arsenic!F8) -> 0.98
B12: Benthic invertebrate | C12: =AVERAGE(methylmercury!F9,divalent_mercury!F10,benzo_a_pyrene!F9,'2_3_7_8_tcdd'!F9,'cadmium'!F9,arsenic!F9) -> 1.0083333 | D12: =MAX(methylmercury!F9,divalent_mercury!F10,benzo_a_pyrene!F9,'2_3_7_8_tcdd'!F9,'cadmium'!F9,arsenic!F9) -> 1.05 | E12: =MIN(methylmercury!F9,divalent_mercury!F10,benzo_a_pyrene!F9,'2_3_7_8_tcdd'!F9,'cadmium'!F9,arsenic!F9) -> 0.98
B13: Benthic omnivore | C13: =AVERAGE(methylmercury!F10,divalent_mercury!F11,benzo_a_pyrene!F10,'2_3_7_8_tcdd'!F10,'cadmium'!F10,arsenic!F10) -> 1.0066667 | D13: =MAX(methylmercury!F10,divalent_mercury!F11,benzo_a_pyrene!F10,'2_3_7_8_tcdd'!F10,'cadmium'!F10,arsenic!F10) -> 1.05 | E13: =MIN(methylmercury!F10,divalent_mercury!F11,benzo_a_pyrene!F10,'2_3_7_8_tcdd'!F10,'cadmium'!F10,arsenic!F10) -> 0.98
B14: Benthic carnivore | C14: =AVERAGE(methylmercury!F11,divalent_mercury!F12,benzo_a_pyrene!F11,'2_3_7_8_tcdd'!F11,'cadmium'!F11,arsenic!F11) -> 1.0066667 | D14: =MAX(methylmercury!F11,divalent_mercury!F12,benzo_a_pyrene!F11,'2_3_7_8_tcdd'!F11,'cadmium'!F11,arsenic!F11) -> 1.05 | E14: =MIN(methylmercury!F11,divalent_mercury!F12,benzo_a_pyrene!F11,'2_3_7_8_tcdd'!F11,'cadmium'!F11,arsenic!F11) -> 0.98
B15: Tilled surface soil | C15: =AVERAGE(methylmercury!F12,divalent_mercury!F13,benzo_a_pyrene!F12,'2_3_7_8_tcdd'!F12,'cadmium'!F12,arsenic!F12) -> 1.0016667 | D15: =MAX(methylmercury!F12,divalent_mercury!F13,benzo_a_pyrene!F12,'2_3_7_8_tcdd'!F12,'cadmium'!F12,arsenic!F12) -> 1.03 | E15: =MIN(methylmercury!F12,divalent_mercury!F13,benzo_a_pyrene!F12,'2_3_7_8_tcdd'!F12,'cadmium'!F12,arsenic!F12) -> 0.99
B16: Untilled surface soil | C16: =AVERAGE(methylmercury!F13,divalent_mercury!F14,benzo_a_pyrene!F13,'2_3_7_8_tcdd'!F13,'cadmium'!F13,arsenic!F13) -> 0.99666667 | D16: =MAX(methylmercury!F13,divalent_mercury!F14,benzo_a_pyrene!F13,'2_3_7_8_tcdd'!F13,'cadmium'!F13,arsenic!F13) -> 1 | E16: =MIN(methylmercury!F13,divalent_mercury!F14,benzo_a_pyrene!F13,'2_3_7_8_tcdd'!F13,'cadmium'!F13,arsenic!F13) -> 0.99
... B26: Grass root | C26: =AVERAGE(methylmercury!F23,divalent_mercury!F24,benzo_a_pyrene!F23,'2_3_7_8_tcdd'!F23,'cadmium'!F23,arsenic!F23) -> 0.99458333 | D26: =MAX(methylmercury!F23,divalent_mercury!F24,benzo_a_pyrene!F23,'2_3_7_8_tcdd'!F23,'cadmium'!F23,arsenic!F23) -> 1.0725 | E26: =MIN(methylmercury!F23,divalent_mercury!F24,benzo_a_pyrene!F23,'2_3_7_8_tcdd'!F23,'cadmium'!F23,arsenic!F23) -> 0.815
B29: Risk-sensitive aquatic compartments (per MIRC protocols)
B30: Risk-sensitive soil compartments (per MIRC protocols)

Sheet methylmercury
A1: Compartment | B1: Ratio | E1: Compartment | F1: Average Ratio PyTRIM:Legacy TRIM
A2: surface_water_in_sw_pond | B2: 1 | E2: Surface water | F2: =B2 -> 1
A3: sediment_in_sed_pond | B3: 1 | E3: Sediment | F3: =B3 -> 1
A4: soil_surface_in_surfsoil_source | B4: 0.99 | E4: Macrophyte | F4: =B44 -> 1
A5: soil_root_zone_in_rootsoil_source | B5: 0.99 | E5: Zooplankton | F5: =B45 -> 1
A6: soil_vadose_zone_in_vadosesoil_source | B6: 0.99 | E6: Water column herbivore | F6: =B46 -> 1
A7: groundwater_in_gw_source | B7: 1 | E7: Water column omnivore | F7: =B47 -> 1
A8: soil_surface_in_surfsoil_n1 | B8: 1.01 | E8: Water column carnivore | F8: =B48 -> 1
A9: soil_root_zone_in_rootsoil_n1 | B9: 0.98 | E9: Benthic invertebrate | F9: =B49 -> 1
A10: soil_vadose_zone_in_vadosesoil_n1 | B10: 0.99 | E10: Benthic omnivore | F10: =B50 -> 1
A11: groundwater_in_gw_n1 | B11: 1.01 | E11: Benthic carnivore | F11: =B51 -> 1
A12: soil_surface_in_surfsoil_n6 | B12: 0.99 | E12: Tilled surface soil | F12: =B12 -> 0.99
A13: soil_root_zone_in_rootsoil_n6 | B13: 0.99 | E13: Untilled surface soil | F13: =B4 -> 0.99
A14: soil_vadose_zone_in_vadosesoil_n6 | B14: 0.99 | E14: Surface soil | F14: =AVERAGE(B8,B16,B20,B24,B28,B32,B36,B40) -> 1.005
A15: groundwater_in_gw_n6 | B15: 1 | E15: Root zone soil | F15: =AVERAGE(B9,B17,B21,B25,B29,B33,B37,B41) -> 0.99875
A16: soil_surface_in_surfsoil_n7 | B16: 1.01 | E16: Vadose zone soil | F16: =AVERAGE(B10,B18,B22,B26,B30,B34,B38,B42) -> 1.00125
A17: soil_root_zone_in_rootsoil_n7 | B17: 0.99 | E17: Groundwater | F17: =AVERAGE(B11,B19,B23,B27,B31,B35,B39,B43) -> 1.0075
A18: soil_vadose_zone_in_vadosesoil_n7 | B18: 1 | E18: Coniferous leaf | F18: =AVERAGE(B64,B66,B72,B74) -> 0
A19: groundwater_in_gw_n7 | B19: 1.01 | E19: Coniferous leaf particle | F19: =AVERAGE(B65,B67,B73,B75) -> 0
A20: soil_surface_in_surfsoil_n3 | B20: 1.01 | E20: Grass leaf | F20: =AVERAGE(B52,B56,B60,B68) -> 0.745
A21: soil_root_zone_in_rootsoil_n3 | B21: 1.01 | E21: Grass leaf particle | F21: =AVERAGE(B53,B57,B61,B69) -> 0.6775
A22: soil_vadose_zone_in_vadosesoil_n3 | B22: 1.01 | E22: Grass stem | F22: =AVERAGE(B54,B58,B62,B70) -> 0.655
A23: groundwater_in_gw_n3 | B23: 1.02 | E23: Grass root | F23: =AVERAGE(B55,B59,B63,B71) -> 0.9975
A24: soil_surface_in_surfsoil_n4 | B24: 1
A25: soil_root_zone_in_rootsoil_n4 | B25: 1
A26: soil_vadose_zone_in_vadosesoil_n4 | B26: 1
A27: groundwater_in_gw_n4 | B27: 1
A28: soil_surface_in_surfsoil_n5 | B28: 1
A29: soil_root_zone_in_rootsoil_n5 | B29: 1
A30: soil_vadose_zone_in_vadosesoil_n5 | B30: 1
A31: groundwater_in_gw_n5 | B31: 1
A32: soil_surface_in_surfsoil_s1 | B32: 1.01
A33: soil_root_zone_in_rootsoil_s1 | B33: 1.01
A34: soil_vadose_zone_in_vadosesoil_s1 | B34: 1.01
A35: groundwater_in_gw_s1 | B35: 1.02
... A79: wetvaporsource_in_wetvaporsource_source | B79: 1

Sheet divalent_mercury
A1: Compartment | B1: Ratio
A2: surface_water_in_sw_pond | B2: 1 | E2: Compartment | F2: Average Ratio PyTRIM:Legacy TRIM
A3: sediment_in_sed_pond | B3: 1 | E3: Surface water | F3: =B3 -> 1
A4: soil_surface_in_surfsoil_source | B4: 0.99 | E4: Sediment | F4: =B4 -> 0.99
A5: soil_root_zone_in_rootsoil_source | B5: 0.99 | E5: Macrophyte | F5: =B44 -> 1
A6: soil_vadose_zone_in_vadosesoil_source | B6: 0.99 | E6: Zooplankton | F6: =B45 -> 1
A7: groundwater_in_gw_source | B7: 1 | E7: Water column herbivore | F7: =B46 -> 1
A8: soil_surface_in_surfsoil_n1 | B8: 1.01 | E8: Water column omnivore | F8: =B47 -> 1
A9: soil_root_zone_in_rootsoil_n1 | B9: 0.98 | E9: Water column carnivore | F9: =B48 -> 1
A10: soil_vadose_zone_in_vadosesoil_n1 | B10: 0.99 | E10: Benthic invertebrate | F10: =B49 -> 1
A11: groundwater_in_gw_n1 | B11: 1.01 | E11: Benthic omnivore | F11: =B50 -> 0.99
A12: soil_surface_in_surfsoil_n6 | B12: 0.99 | E12: Benthic carnivore | F12: =B51 -> 0.99
A13: soil_root_zone_in_rootsoil_n6 | B13: 0.99 | E13: Tilled surface soil | F13: =B13 -> 0.99
A14: soil_vadose_zone_in_vadosesoil_n6 | B14: 0.99 | E14: Untilled surface soil | F14: =B5 -> 0.99
A15: groundwater_in_gw_n6 | B15: 1 | E15: Surface soil | F15: =AVERAGE(B9,B17,B21,B25,B29,B33,B37,B41) -> 0.99875
A16: soil_surface_in_surfsoil_n7 | B16: 1.01 | E16: Root zone soil | F16: =AVERAGE(B10,B18,B22,B26,B30,B34,B38,B42) -> 1.00125
A17: soil_root_zone_in_rootsoil_n7 | B17: 0.99 | E17: Vadose zone soil | F17: =AVERAGE(B11,B19,B23,B27,B31,B35,B39,B43) -> 1.0075
A18: soil_vadose_zone_in_vadosesoil_n7 | B18: 1 | E18: Groundwater | F18: =AVERAGE(B12,B20,B24,B28,B32,B36,B40,B44) -> 1.00125
A19: groundwater_in_gw_n7 | B19: 1.01 | E19: Coniferous leaf | F19: =AVERAGE(B65,B67,B73,B75) -> 0.99
A20: soil_surface_in_surfsoil_n3 | B20: 1.01 | E20: Coniferous leaf particle | F20: =AVERAGE(B66,B68,B74,B76) -> 0.9025
A21: soil_root_zone_in_rootsoil_n3 | B21: 1.01 | E21: Grass leaf | F21: =AVERAGE(B53,B57,B61,B69) -> 1.0625
A22: soil_vadose_zone_in_vadosesoil_n3 | B22: 1.01 | E22: Grass leaf particle | F22: =AVERAGE(B54,B58,B62,B70) -> 0.36
A23: groundwater_in_gw_n3 | B23: 1.02 | E23: Grass stem | F23: =AVERAGE(B55,B59,B63,B71) -> 0.9975
A24: soil_surface_in_surfsoil_n4 | B24: 1 | E24: Grass root | F24: =AVERAGE(B56,B60,B64,B72) -> 0.815
A25: soil_root_zone_in_rootsoil_n4 | B25: 1
A26: soil_vadose_zone_in_vadosesoil_n4 | B26: 1
A27: groundwater_in_gw_n4 | B27: 1
A28: soil_surface_in_surfsoil_n5 | B28: 1
A29: soil_root_zone_in_rootsoil_n5 | B29: 1
A30: soil_vadose_zone_in_vadosesoil_n5 | B30: 1
A31: groundwater_in_gw_n5 | B31: 1
A32: soil_surface_in_surfsoil_s1 | B32: 1.01
A33: soil_root_zone_in_rootsoil_s1 | B33: 1.01
A34: soil_vadose_zone_in_vadosesoil_s1 | B34: 1.01
A35: groundwater_in_gw_s1 | B35: 1.02
A36: soil_surface_in_surfsoil_s4 | B36: 1
... A79: wetvaporsource_in_wetvaporsource_source | B79: 1

Sheet elemental_mercury
A1: Compartment | B1: Ratio
A2: surface_water_in_sw_pond | B2: 1
A3: sediment_in_sed_pond | B3: 1
A4: soil_surface_in_surfsoil_source | B4: 1
A5: soil_root_zone_in_rootsoil_source | B5: 1
A6: soil_vadose_zone_in_vadosesoil_source | B6: 1
A7: groundwater_in_gw_source | B7: 1
A8: soil_surface_in_surfsoil_n1 | B8: 1.02
A9: soil_root_zone_in_rootsoil_n1 | B9: 1
A10: soil_vadose_zone_in_vadosesoil_n1 | B10: 1
A11: groundwater_in_gw_n1 | B11: 1.01
A12: soil_surface_in_surfsoil_n6 | B12: 1
A13: soil_root_zone_in_rootsoil_n6 | B13: 1
... A21: soil_root_zone_in_rootsoil_n3 | B21: 1.02
A22: soil_vadose_zone_in_vadosesoil_n3 | B22: 1.02 | E22: Compartment | F22: Average Ratio PyTRIM:Legacy TRIM
A23: groundwater_in_gw_n3 | B23: 1.02 | E23: Surface water | F23: =B23 -> 1.02
A24: soil_surface_in_surfsoil_n4 | B24: 1 | E24: Sediment | F24: =B24 -> 1
A25: soil_root_zone_in_rootsoil_n4 | B25: 1 | E25: Macrophyte | F25: =B65 -> 0.61
A26: soil_vadose_zone_in_vadosesoil_n4 | B26: 1 | E26: Zooplankton | F26: =B66 -> 0.61
A27: groundwater_in_gw_n4 | B27: 1 | E27: Water column herbivore | F27: =B67 -> 0.61
A28: soil_surface_in_surfsoil_n5 | B28: 1 | E28: Water column omnivore | F28: =B68 -> 0.85
A29: soil_root_zone_in_rootsoil_n5 | B29: 1 | E29: Water column carnivore | F29: =B69 -> 0.77
A30: soil_vadose_zone_in_vadosesoil_n5 | B30: 1 | E30: Benthic invertebrate | F30: =B70 -> 0.58
A31: groundwater_in_gw_n5 | B31: 1 | E31: Benthic omnivore | F31: =B71 -> 1
A32: soil_surface_in_surfsoil_s1 | B32: 1.02 | E32: Benthic carnivore | F32: =B72 -> 0.61
A33: soil_root_zone_in_rootsoil_s1 | B33: 1.02 | E33: Untilled surface soil | F33: =B33 -> 1.02
A34: soil_vadose_zone_in_vadosesoil_s1 | B34: 1.02 | E34: Vegetationless surface soil | F34: =B25 -> 1
A35: groundwater_in_gw_s1 | B35: 1.02 | E35: Surface soil | F35: =AVERAGE(B29,B37,B41,B45,B49,B53,B57,B61) -> 0.91375
A36: soil_surface_in_surfsoil_s4 | B36: 1 | E36: Root zone soil | F36: =AVERAGE(B30,B38,B42,B46,B50,B54,B58,B62) -> 0.8425
A37: soil_root_zone_in_rootsoil_s4 | B37: 1 | E37: Vadose zone soil | F37: =AVERAGE(B31,B39,B43,B47,B51,B55,B59,B63) -> 1
A38: soil_vadose_zone_in_vadosesoil_s4 | B38: 1 | E38: Groundwater | F38: =AVERAGE(B32,B40,B44,B48,B52,B56,B60,B64) -> 0.7725
A39: groundwater_in_gw_s4 | B39: 1 | E39: Coniferous leaf | F39: 1
A40: soil_surface_in_surfsoil_s5 | B40: 1 | E40: Coniferous leaf particle | F40: 1
A41: soil_root_zone_in_rootsoil_s5 | B41: 1 | E41: Grass leaf | F41: =AVERAGE(B73,B77,B81,B89) -> 0.8
A42: soil_vadose_zone_in_vadosesoil_s5 | B42: 1 | E42: Grass leaf particle | F42: =AVERAGE(B74,B78,B82,B90) -> 0.805
A43: groundwater_in_gw_s5 | B43: 1 | E43: Grass stem | F43: =AVERAGE(B75,B79,B83,B91) -> 0.805
A44: macrophyte_in_sw_pond | B44: 0 | E44: Grass root | F44: =AVERAGE(B76,B80,B84,B92) -> 1
A45: zooplankton_in_sw_pond | B45: 1
A46: water_column_herbivore_in_sw_pond | B46: 1
A47: water_column_omnivore_in_sw_pond | B47: 1
...

Sheet benzo_a_pyrene
A1: Compartment | B1: Ratio | E1: Compartment | F1: Average Ratio PyTRIM:Legacy TRIM
A2: surface_water_in_sw_pond | B2: 1.01 | E2: Surface water | F2: =B2 -> 1.01
A3: sediment_in_sed_pond | B3: 1.01 | E3: Sediment | F3: =B3 -> 1.01
A4: soil_surface_in_surfsoil_source | B4: 1 | E4: Macrophyte | F4: =B44 -> 1.01
A5: soil_root_zone_in_rootsoil_source | B5: 1 | E5: Zooplankton | F5: =B45 -> 1.01
A6: soil_vadose_zone_in_vadosesoil_source | B6: 1 | E6: Water column herbivore | F6: =B46 -> 1.01
A7: groundwater_in_gw_source | B7: 1 | E7: Water column omnivore | F7: =B47 -> 1.01
A8: soil_surface_in_surfsoil_n1 | B8: 1.05 | E8: Water column carnivore | F8: =B48 -> 1.01
A9: soil_root_zone_in_rootsoil_n1 | B9: 1.05 | E9: Benthic invertebrate | F9: =B49 -> 1.01
A10: soil_vadose_zone_in_vadosesoil_n1 | B10: 1.05 | E10: Benthic omnivore | F10: =B50 -> 1.01
A11: groundwater_in_gw_n1 | B11: 1.05 | E11: Benthic carnivore | F11: =B51 -> 1.01
A12: soil_surface_in_surfsoil_n6 | B12: 1 | E12: Tilled surface soil | F12: =B12 -> 1
A13: soil_root_zone_in_rootsoil_n6 | B13: 1 | E13: Untilled surface soil | F13: =B4 -> 1
A14: soil_vadose_zone_in_vadosesoil_n6 | B14: 1 | E14: Surface soil | F14: =AVERAGE(B8,B16,B20,B24,B28,B32,B36,B40) -> 1.025
A15: groundwater_in_gw_n6 | B15: 1 | E15: Root zone soil | F15: =AVERAGE(B9,B17,B21,B25,B29,B33,B37,B41) -> 1.02625
A16: soil_surface_in_surfsoil_n7 | B16: 1.05 | E16: Vadose zone soil | F16: =AVERAGE(B10,B18,B22,B26,B30,B34,B38,B42) -> 1.02625
A17: soil_root_zone_in_rootsoil_n7 | B17: 1.05 | E17: Groundwater | F17: =AVERAGE(B11,B19,B23,B27,B31,B35,B39,B43) -> 1.02625
A18: soil_vadose_zone_in_vadosesoil_n7 | B18: 1.05 | E18: Coniferous leaf | F18: =AVERAGE(B64,B66,B72,B74) -> 0.99
A19: groundwater_in_gw_n7 | B19: 1.05 | E19: Coniferous leaf particle | F19: =AVERAGE(B65,B67,B73,B75) -> 1
A20: soil_surface_in_surfsoil_n3 | B20: 1.05 | E20: Grass leaf | F20: =AVERAGE(B52,B56,B60,B68) -> 1.29
A21: soil_root_zone_in_rootsoil_n3 | B21: 1.05 | E21: Grass leaf particle | F21: =AVERAGE(B53,B57,B61,B69) -> 1.29
A22: soil_vadose_zone_in_vadosesoil_n3 | B22: 1.05 | E22: Grass stem | F22: =AVERAGE(B54,B58,B62,B70) -> 0.88
A23: groundwater_in_gw_n3 | B23: 1.05 | E23: Grass root | F23: =AVERAGE(B55,B59,B63,B71) -> 1.0525
A24: soil_surface_in_surfsoil_n4 | B24: 1
A25: soil_root_zone_in_rootsoil_n4 | B25: 1
A26: soil_vadose_zone_in_vadosesoil_n4 | B26: 1
A27: groundwater_in_gw_n4 | B27: 1
A28: soil_surface_in_surfsoil_n5 | B28: 1
A29: soil_root_zone_in_rootsoil_n5 | B29: 1
A30: soil_vadose_zone_in_vadosesoil_n5 | B30: 1
A31: groundwater_in_gw_n5 | B31: 1
A32: soil_surface_in_surfsoil_s1 | B32: 1.05
A33: soil_root_zone_in_rootsoil_s1 | B33: 1.06
A34: soil_vadose_zone_in_vadosesoil_s1 | B34: 1.06
A35: groundwater_in_gw_s1 | B35: 1.06
... A79: wetvaporsource_in_wetvaporsource_source | B79: 1

Sheet 2_3_7_8_tcdd
A1: Compartment | B1: Ratio | E1: Compartment | F1: Average Ratio PyTRIM:Legacy TRIM
A2: surface_water_in_sw_pond | B2: 0.98 | E2: Surface water | F2: =B2 -> 0.98
A3: sediment_in_sed_pond | B3: 0.98 | E3: Sediment | F3: =B3 -> 0.98
A4: soil_surface_in_surfsoil_source | B4: 1 | E4: Macrophyte | F4: =B44 -> 0.98
A5: soil_root_zone_in_rootsoil_source | B5: 1 | E5: Zooplankton | F5: =B45 -> 0.98
A6: soil_vadose_zone_in_vadosesoil_source | B6: 1 | E6: Water column herbivore | F6: =B46 -> 0.98
A7: groundwater_in_gw_source | B7: 1 | E7: Water column omnivore | F7: =B47 -> 0.98
A8: soil_surface_in_surfsoil_n1 | B8: 1.08 | E8: Water column carnivore | F8: =B48 -> 0.98
A9: soil_root_zone_in_rootsoil_n1 | B9: 1.07 | E9: Benthic invertebrate | F9: =B49 -> 0.98
A10: soil_vadose_zone_in_vadosesoil_n1 | B10: 1.07 | E10: Benthic omnivore | F10: =B50 -> 0.98
A11: groundwater_in_gw_n1 | B11: 1.07 | E11: Benthic carnivore | F11: =B51 -> 0.98
A12: soil_surface_in_surfsoil_n6 | B12: 1 | E12: Tilled surface soil | F12: =B12 -> 1
A13: soil_root_zone_in_rootsoil_n6 | B13: 1 | E13: Untilled surface soil | F13: =B4 -> 1
A14: soil_vadose_zone_in_vadosesoil_n6 | B14: 1 | E14: Surface soil | F14: =AVERAGE(B8,B16,B20,B24,B28,B32,B36,B40) -> 1.0225
A15: groundwater_in_gw_n6 | B15: 1 | E15: Root zone soil | F15: =AVERAGE(B9,B17,B21,B25,B29,B33,B37,B41) -> 1.02125
A16: soil_surface_in_surfsoil_n7 | B16: 1.06 | E16: Vadose zone soil | F16: =AVERAGE(B10,B18,B22,B26,B30,B34,B38,B42) -> 1.02125
A17: soil_root_zone_in_rootsoil_n7 | B17: 1.06 | E17: Groundwater | F17: =AVERAGE(B11,B19,B23,B27,B31,B35,B39,B43) -> 1.02125
A18: soil_vadose_zone_in_vadosesoil_n7 | B18: 1.06 | E18: Coniferous leaf | F18: =AVERAGE(B64,B66,B72,B74) -> 0.94
A19: groundwater_in_gw_n7 | B19: 1.06 | E19: Coniferous leaf particle | F19: =AVERAGE(B65,B67,B73,B75) -> 0.68
A20: soil_surface_in_surfsoil_n3 | B20: 1.08 | E20: Grass leaf | F20: =AVERAGE(B52,B56,B60,B68) -> 0.91
A21: soil_root_zone_in_rootsoil_n3 | B21: 1.08 | E21: Grass leaf particle | F21: =AVERAGE(B53,B57,B61,B69) -> 1.2725
A22: soil_vadose_zone_in_vadosesoil_n3 | B22: 1.08 | E22: Grass stem | F22: =AVERAGE(B54,B58,B62,B70) -> 0.58
A23: groundwater_in_gw_n3 | B23: 1.08 | E23: Grass root | F23: =AVERAGE(B55,B59,B63,B71) -> 1.0725
A24: soil_surface_in_surfsoil_n4 | B24: 0.97
A25: soil_root_zone_in_rootsoil_n4 | B25: 0.97
A26: soil_vadose_zone_in_vadosesoil_n4 | B26: 0.97
A27: groundwater_in_gw_n4 | B27: 0.97
A28: soil_surface_in_surfsoil_n5 | B28: 0.97
A29: soil_root_zone_in_rootsoil_n5 | B29: 0.97
A30: soil_vadose_zone_in_vadosesoil_n5 | B30: 0.97
A31: groundwater_in_gw_n5 | B31: 0.97
A32: soil_surface_in_surfsoil_s1 | B32: 1.08
A33: soil_root_zone_in_rootsoil_s1 | B33: 1.08
A34: soil_vadose_zone_in_vadosesoil_s1 | B34: 1.08
A35: groundwater_in_gw_s1 | B35: 1.08
... A79: wetvaporsource_in_wetvaporsource_source | B79: 1

Sheet cadmium
A1: Compartment | B1: Ratio | E1: Compartment | F1: Average Ratio PyTRIM:Legacy TRIM
A2: surface_water_in_sw_pond | B2: 1.05 | E2: Surface water | F2: =B2 -> 1.05
A3: sediment_in_sed_pond | B3: 1.05 | E3: Sediment | F3: =B3 -> 1.05
A4: soil_surface_in_surfsoil_source | B4: 1 | E4: Macrophyte | F4: =B44 -> 1.05
A5: soil_root_zone_in_rootsoil_source | B5: 1 | E5: Zooplankton | F5: =B45 -> 1.05
A6: soil_vadose_zone_in_vadosesoil_source | B6: 1 | E6: Water column herbivore | F6: =B46 -> 1.05
A7: groundwater_in_gw_source | B7: 1 | E7: Water column omnivore | F7: =B47 -> 1.05
A8: soil_surface_in_surfsoil_n1 | B8: 1.03 | E8: Water column carnivore | F8: =B48 -> 1.05
A9: soil_root_zone_in_rootsoil_n1 | B9: 0.98 | E9: Benthic invertebrate | F9: =B49 -> 1.05
A10: soil_vadose_zone_in_vadosesoil_n1 | B10: 0.99 | E10: Benthic omnivore | F10: =B50 -> 1.05
A11: groundwater_in_gw_n1 | B11: 1 | E11: Benthic carnivore | F11: =B51 -> 1.05
A12: soil_surface_in_surfsoil_n6 | B12: 1.03 | E12: Tilled surface soil | F12: =B12 -> 1.03
A13: soil_root_zone_in_rootsoil_n6 | B13: 1.02 | E13: Untilled surface soil | F13: =B4 -> 1
A14: soil_vadose_zone_in_vadosesoil_n6 | B14: 1.01 | E14: Surface soil | F14: =AVERAGE(B8,B16,B20,B24,B28,B32,B36,B40) -> 1.04125
A15: groundwater_in_gw_n6 | B15: 1.01 | E15: Root zone soil | F15: =AVERAGE(B9,B17,B21,B25,B29,B33,B37,B41) -> 1.03
A16: soil_surface_in_surfsoil_n7 | B16: 1.03 | E16: Vadose zone soil | F16: =AVERAGE(B10,B18,B22,B26,B30,B34,B38,B42) -> 1.03125
A17: soil_root_zone_in_rootsoil_n7 | B17: 1 | E17: Groundwater | F17: =AVERAGE(B11,B19,B23,B27,B31,B35,B39,B43) -> 1.03375
A18: soil_vadose_zone_in_vadosesoil_n7 | B18: 1 | E18: Coniferous leaf | F18: =AVERAGE(B64,B66,B72,B74) -> 0.91
A19: groundwater_in_gw_n7 | B19: 1.01 | E19: Coniferous leaf particle | F19: =AVERAGE(B65,B67,B73,B75) -> 0.91
A20: soil_surface_in_surfsoil_n3 | B20: 1.04 | E20: Grass leaf | F20: =AVERAGE(B52,B56,B60,B68) -> 0.715
A21: soil_root_zone_in_rootsoil_n3 | B21: 1.03 | E21: Grass leaf particle | F21: =AVERAGE(B53,B57,B61,B69) -> 1.02
A22: soil_vadose_zone_in_vadosesoil_n3 | B22: 1.03 | E22: Grass stem | F22: =AVERAGE(B54,B58,B62,B70) -> 0.4
A23: groundwater_in_gw_n3 | B23: 1.03 | E23: Grass root | F23: =AVERAGE(B55,B59,B63,B71) -> 1.0125
A24: soil_surface_in_surfsoil_n4 | B24: 1.05
A25: soil_root_zone_in_rootsoil_n4 | B25: 1.05
A26: soil_vadose_zone_in_vadosesoil_n4 | B26: 1.05
A27: groundwater_in_gw_n4 | B27: 1.05
A28: soil_surface_in_surfsoil_n5 | B28: 1.05
A29: soil_root_zone_in_rootsoil_n5 | B29: 1.05
A30: soil_vadose_zone_in_vadosesoil_n5 | B30: 1.05
A31: groundwater_in_gw_n5 | B31: 1.05
A32: soil_surface_in_surfsoil_s1 | B32: 1.03
A33: soil_root_zone_in_rootsoil_s1 | B33: 1.03
A34: soil_vadose_zone_in_vadosesoil_s1 | B34: 1.03
A35: groundwater_in_gw_s1 | B35: 1.03
... A79: wetvaporsource_in_wetvaporsource_source | B79: 1

Sheet arsenic
A1: Compartment | B1: Ratio | E1: Compartment | F1: Average Ratio PyTRIM:Legacy TRIM
A2: surface_water_in_sw_pond | B2: 1.01 | E2: Surface water | F2: =B2 -> 1.01
A3: sediment_in_sed_pond | B3: 1.01 | E3: Sediment | F3: =B3 -> 1.01
A4: soil_surface_in_surfsoil_source | B4: 1 | E4: Macrophyte | F4: =$F$2 -> 1.01
A5: soil_root_zone_in_rootsoil_source | B5: 1 | E5: Zooplankton | F5: =$F$2 -> 1.01
A6: soil_vadose_zone_in_vadosesoil_source | B6: 1 | E6: Water column herbivore | F6: =$F$2 -> 1.01
A7: groundwater_in_gw_source | B7: 0.99 | E7: Water column omnivore | F7: =$F$2 -> 1.01
A8: soil_surface_in_surfsoil_n1 | B8: 1.03 | E8: Water column carnivore | F8: =$F$2 -> 1.01
A9: soil_root_zone_in_rootsoil_n1 | B9: 1 | E9: Benthic invertebrate | F9: =$F$2 -> 1.01
A10: soil_vadose_zone_in_vadosesoil_n1 | B10: 1 | E10: Benthic omnivore | F10: =$F$2 -> 1.01
A11: groundwater_in_gw_n1 | B11: 1 | E11: Benthic carnivore | F11: =$F$2 -> 1.01
A12: soil_surface_in_surfsoil_n6 | B12: 1 | E12: Tilled surface soil | F12: =B12 -> 1
A13: soil_root_zone_in_rootsoil_n6 | B13: 1 | E13: Untilled surface soil | F13: =B4 -> 1
A14: soil_vadose_zone_in_vadosesoil_n6 | B14: 1 | E14: Surface soil | F14: =AVERAGE(B8,B16,B20,B24,B28,B32,B36,B40) -> 1.02
A15: groundwater_in_gw_n6 | B15: 1 | E15: Root zone soil | F15: =AVERAGE(B9,B17,B21,B25,B29,B33,B37,B41) -> 1.01375
A16: soil_surface_in_surfsoil_n7 | B16: 1.03 | E16: Vadose zone soil | F16: =AVERAGE(B10,B18,B22,B26,B30,B34,B38,B42) -> 1.01375
A17: soil_root_zone_in_rootsoil_n7 | B17: 1.01 | E17: Groundwater | F17: =AVERAGE(B11,B19,B23,B27,B31,B35,B39,B43) -> 1.015
A18: soil_vadose_zone_in_vadosesoil_n7 | B18: 1.01 | E18: Coniferous leaf | F18: =AVERAGE(B64,B66,B72,B74) -> 0.99
A19: groundwater_in_gw_n7 | B19: 1.02 | E19: Coniferous leaf particle | F19: =AVERAGE(B65,B67,B73,B75) -> 0.99
A20: soil_surface_in_surfsoil_n3 | B20: 1.03 | E20: Grass leaf | F20: =AVERAGE(B52,B56,B60,B68) -> 0.71
A21: soil_root_zone_in_rootsoil_n3 | B21: 1.03 | E21: Grass leaf particle | F21: =AVERAGE(B53,B57,B61,B69) -> 1.3
A22: soil_vadose_zone_in_vadosesoil_n3 | B22: 1.03 | E22: Grass stem | F22: =AVERAGE(B54,B58,B62,B70) -> 0.39
A23: groundwater_in_gw_n3 | B23: 1.03 | E23: Grass root | F23: =AVERAGE(B55,B59,B63,B71) -> 1.0175
A24: soil_surface_in_surfsoil_n4 | B24: 1.01
A25: soil_root_zone_in_rootsoil_n4 | B25: 1.01
A26: soil_vadose_zone_in_vadosesoil_n4 | B26: 1.01
A27: groundwater_in_gw_n4 | B27: 1.01
A28: soil_surface_in_surfsoil_n5 | B28: 1.01
A29: soil_root_zone_in_rootsoil_n5 | B29: 1.01
A30: soil_vadose_zone_in_vadosesoil_n5 | B30: 1.01
A31: groundwater_in_gw_n5 | B31: 1.01
A32: soil_surface_in_surfsoil_s1 | B32: 1.03
A33: soil_root_zone_in_rootsoil_s1 | B33: 1.03
A34: soil_vadose_zone_in_vadosesoil_s1 | B34: 1.03
A35: groundwater_in_gw_s1 | B35: 1.03
... A79: wetvaporsource_in_wetvaporsource_source | B79: 1

Sheet lead
A1: Compartment | B1: Ratio | C1: Column1 | E1: Compartment | F1: Average Ratio PyTRIM:Legacy TRIM
A2: surface_water_in_sw_pond | B2: 1.04 | E2: Surface water | F2: =B2 -> 1.04
A3: sediment_in_sed_pond | B3: 1.04 | E3: Sediment | F3: =B3 -> 1.04
A4: soil_surface_in_surfsoil_source | B4: 1 | E4: Macrophyte | F4: =B44 -> 1
A5: soil_root_zone_in_rootsoil_source | B5: 0.99 | E5: Zooplankton | F5: =B45 -> 1
A6: soil_vadose_zone_in_vadosesoil_source | B6: 0.97 | E6: Water column herbivore | F6: 1
A7: groundwater_in_gw_source | B7: 0.96 | E7: Water column omnivore | F7: 1
A8: soil_surface_in_surfsoil_n1 | B8: 1.04 | E8: Water column carnivore | F8: 1
A9: soil_root_zone_in_rootsoil_n1 | B9: 0.95 | E9: Benthic invertebrate | F9: =B49 -> 1.04
A10: soil_vadose_zone_in_vadosesoil_n1 | B10: 0.96 | E10: Benthic omnivore | F10: =B50 -> 1.11
A11: groundwater_in_gw_n1 | B11: 0.96 | E11: Benthic carnivore | F11: =B51 -> 1.13
A12: soil_surface_in_surfsoil_n6 | B12: 1.2 | E12: Untilled surface soil | F12: =B12 -> 1.2
A13: soil_root_zone_in_rootsoil_n6 | B13: 1.11 | E13: Vegetationless surface soil | F13: =B4 -> 1
A14: soil_vadose_zone_in_vadosesoil_n6 | B14: 1.07 | E14: Surface soil | F14: =AVERAGE(B8,B16,B20,B24,B28,B32,B36,B40) -> 1.0525
A15: groundwater_in_gw_n6 | B15: 1.04 | E15: Root zone soil | F15: =AVERAGE(B9,B17,B21,B25,B29,B33,B37,B41) -> 1.025
A16: soil_surface_in_surfsoil_n7 | B16: 1.05 | E16: Vadose zone soil | F16: =AVERAGE(B10,B18,B22,B26,B30,B34,B38,B42) -> 1.01375
A17: soil_root_zone_in_rootsoil_n7 | B17: 0.99 | E17: Groundwater | F17: =AVERAGE(B11,B19,B23,B27,B31,B35,B39,B43) -> 1.005
A18: soil_vadose_zone_in_vadosesoil_n7 | B18: 0.99 | E18: Coniferous leaf | F18: =AVERAGE(B64,B66,B72,B74) -> 1
A19: groundwater_in_gw_n7 | B19: 0.98 | E19: Coniferous leaf particle | F19: =AVERAGE(B65,B67,B73,B75) -> 0.73
A20: soil_surface_in_surfsoil_n3 | B20: 1.05 | E20: Grass leaf | F20: =AVERAGE(B52,B56,B60,B68) -> 1
A21: soil_root_zone_in_rootsoil_n3 | B21: 1.03 | E21: Grass leaf particle | F21: =AVERAGE(B53,B57,B61,B69) -> 32.8925
A22: soil_vadose_zone_in_vadosesoil_n3 | B22: 1.02 | E22: Grass stem | F22: =AVERAGE(B54,B58,B62,B70) -> 1
A23: groundwater_in_gw_n3 | B23: 1.01 | E23: Grass root | F23: =AVERAGE(B55,B59,B63,B71) -> 1
A24: soil_surface_in_surfsoil_n4 | B24: 1.06
A25: soil_root_zone_in_rootsoil_n4 | B25: 1.05
A26: soil_vadose_zone_in_vadosesoil_n4 | B26: 1.03
A27: groundwater_in_gw_n4 | B27: 1.02
A28: soil_surface_in_surfsoil_n5 | B28: 1.06
A29: soil_root_zone_in_rootsoil_n5 | B29: 1.05
A30: soil_vadose_zone_in_vadosesoil_n5 | B30: 1.03
A31: groundwater_in_gw_n5 | B31: 1.02
A32: soil_surface_in_surfsoil_s1 | B32: 1.04
A33: soil_root_zone_in_rootsoil_s1 | B33: 1.03
A34: soil_vadose_zone_in_vadosesoil_s1 | B34: 1.02
A35: groundwater_in_gw_s1 | B35: 1.01
... A45: zooplankton_in_sw_pond | B45: 1
A46: water_column_herbivore_in_sw_pond | B46: inf
A47: water_column_omnivore_in_sw_pond | B47: inf
A48: water_column_carnivore_in_sw_pond | B48: inf
A49: benthic_invertebrate_in_sed_pond | B49: 1.04
...
